Workbook

Sheet Read Me
B2: AUTO SALES EXECUTIVE - M0 Balance Model & Paper Prototype
B5: WHAT THIS IS
B6: M0 from DESIGN.md section 12. Its only job is to answer one question before a single line of Godot code gets written:
B7: Is the negotiation loop actually fun?
B8: Done means: you would play a second round. If the answer is no, the correct outcome is to change DESIGN.md - not to build M1 anyway.
B10: THE CUSTOMER FIGHTS BACK
B11: Every turn the customer raises an OBJECTION, and you can see it coming before you commit. Each objection damages patience; some also carry a RIDER - an extra nasty effect.
B12: Rapport is a SHIELD, not a heal. It absorbs this turn's objection damage and any unused shield EXPIRES at end of turn. Patience only ever goes down.
B13: Any Rapport card reduces the damage. But a rider can only be stopped by the SPECIFIC counter card that answers that objection - generic shield never stops a rider.
B14: That is the whole tension: energy spent defending is energy not spent building the deal.
B16: THE FOUR QUESTIONS M0 MUST ANSWER
B17: 1. Is there a non-obvious decision every turn, or does one line dominate?
... B52: Which single number would you change first?

Sheet Assumptions
A1: ASSUMPTIONS - every global tuning lever lives here
A2: Blue cells are inputs. Nothing else in this workbook hardcodes these numbers.
A3: Lever | B3: Value | C3: Notes
A4: Starting Energy per Turn | B4: 3 | C4: Refills each turn. The resource objections compete for.
A5: Turns Modelled | B5: 12 | C5: Length of the Turn State table on Encounter Sim.
A6: Default Starting Patience | B6: 50 | C6: Reference only - each archetype sets its own.
A7: Passive Patience Decay / Turn | B7: 2 | C7: Small floor of urgency. Objections do most of the damage now.
A8: Sale Threshold (% of Budget) | B8: 0.6 | C8: Deal Value at or above this allows a Sale.
A9: Strong Close Threshold (% of Budget) | B9: 0.8 | C9: Middle tier - the reason to push past a plain Sale.
A10: Max Close Threshold (% of Budget) | B10: 1 | C10: Draining 100% of Budget. Jackpot + reward pick.
A11: Commission Rate | B11: 0.12 | C11: Commission = Deal Value x this rate x the tier multiplier.
A12: Sale Multiplier | B12: 1 | C12: Tier multiplier at 60%.
A13: Strong Close Multiplier | B13: 1.25 | C13: Tier multiplier at 80%.
A14: Max Close Multiplier | B14: 1.5 | C14: Tier multiplier at 100%.
A15: Card Value Scale | B15: 1.65 | C15: Global multiplier on every card's deal value. THE main tuning dial.
... A18: Cards Drawn per Turn | B18: 5 | C18: Used by sim.py only.
A20: Source: first-pass designer estimates from DESIGN.md section 6, retuned after the objection system landed. All provisional - M0 exists to find out which are wrong.

Sheet Objections
A1: OBJECTIONS - what the customer does to you
A2: Every objection damages patience. Some carry a rider, which ONLY the matching counter card can stop.
A3: ID | B3: Name | C3: Base Damage | D3: Rider Type | E3: Rider Lane | F3: Rider Amount | G3: Countered By | H3: Flavour
A4: price_objection | B4: It's Out Of My Budget | C4: 10 | D4: - | E4: - | F4: 0 | G4: - | H4: The number has not changed in twenty minutes. They will say it again.
A5: competitor_quote | B5: The Dealer Down The Road | C5: 7 | D5: raise_resistance | E5: vehicle | F5: 0.15 | G5: Beat The Quote | H5: They have a screenshot. It is from a different model year. It does not matter.
A6: dont_need_extras | B6: I Don't Need All These Extras | C6: 6 | D6: lock_lane | E6: protection | F6: 0 | G6: Justify The Value | H6: Somebody's brother-in-law told them warranties are a scam. Their brother-in-law is right.
A7: talk_to_spouse | B7: Let Me Talk To My Spouse | C7: 4 | D7: drain_energy | E7: - | F7: 1 | G7: Create Urgency | H7: They are going to step outside and call nobody.
A8: preapproved | B8: I'm Pre-Approved At My Credit Union | C8: 7 | D8: shave_value | E8: financing | F8: 0.15 | G8: Reframe The Rate | H8: Financing was where the money was. They have found this out.
A10: raise_resistance - adds Rider Amount to that lane's resistance. Undoes your probing.
A11: lock_lane - that lane accepts no value for one turn.
A12: drain_energy - you lose Rider Amount energy next turn.
A13: shave_value - removes Rider Amount (as a fraction) of the deal value you have built.
A14: Damage shown here is the BASE. Actual damage grows each turn by the escalation rate.

Sheet Cards
A1: CARD POOL - 22 cards. The 10 flagged STARTER make the M0 starting deck.
A2: Deal Value is a SHARE OF THE CUSTOMER'S BUDGET, not dollars. Columns export cleanly to JSON for the Godot /data folder later.
A3: ID | B3: Name | C3: Lane | D3: Energy | E3: Patience Cost | F3: Effect Type | G3: Deal Value (% budget) | H3: Res. Reduction | I3: Shield | J3: Counters | K3: Draw | L3: Buff Next | M3: Upgrade Value | N3: Rarity | O3: Starter | P3: Value @ $30k | Q3: Flavour
A4: base_trim_pitch | B4: Base Trim Pitch | C4: vehicle | D4: 1 | E4: 0 | F4: add_deal_value | G4: 0.0833 | H4: 0 | I4: 0 | K4: 0 | L4: 0 | M4: 0.1167 | N4: starter | O4: YES | P4: =$G4*30000*Assumptions!$B$15 -> 4123.35 | Q4: It's the same car, just with fewer things that work.
A5: upsell_package | B5: Upsell Package | C5: vehicle | D5: 2 | E5: 3 | F5: add_deal_value | G5: 0.1667 | H5: 0 | I5: 0 | K5: 0 | L5: 0 | M5: 0.2267 | N5: common | O5: YES | P5: =$G5*30000*Assumptions!$B$15 -> 8251.65 | Q5: The Platinum Ultra trim adds heated cupholders and five grand.
A6: highlight_features | B6: Highlight Features | C6: vehicle | D6: 1 | E6: 0 | F6: reduce_resistance | G6: 0 | H6: 0.15 | I6: 0 | K6: 0 | L6: 0 | M6: 0 | N6: common | O6: YES | P6: =$G6*30000*Assumptions!$B$15 -> 0 | Q6: Watch me open the trunk with my foot. Now you need it.
A7: extended_warranty | B7: Extended Warranty | C7: protection | D7: 2 | E7: 4 | F7: add_deal_value | G7: 0.1333 | H7: 0 | I7: 0 | K7: 0 | L7: 0 | M7: 0.18 | N7: common | O7: YES | P7: =$G7*30000*Assumptions!$B$15 -> 6598.35 | Q7: Statistically you will never use this. Emotionally, you need it.
A8: gap_insurance | B8: Gap Insurance | C8: protection | D8: 1 | E8: 2 | F8: add_deal_value | G8: 0.0733 | H8: 0 | I8: 0 | K8: 0 | L8: 0 | M8: 0.1 | N8: starter | P8: =$G8*30000*Assumptions!$B$15 -> 3628.35 | Q8: In case the car dies before the loan does.
A9: paint_protection | B9: Paint Protection | C9: protection | D9: 1 | E9: 3 | F9: add_deal_value | G9: 0.06 | H9: 0 | I9: 0 | K9: 0 | L9: 0 | M9: 0.0833 | N9: common | P9: =$G9*30000*Assumptions!$B$15 -> 2970 | Q9: It's wax. It is forty dollars of wax.
A10: rate_markup | B10: Rate Markup | C10: financing | D10: 1 | E10: 5 | F10: add_deal_value | G10: 0.0667 | H10: 0 | I10: 0 | K10: 0 | L10: 0 | M10: 0.0933 | N10: starter | O10: YES | P10: =$G10*30000*Assumptions!$B$15 -> 3301.65 | Q10: The bank said 4.9. I'm going to say 7.9 and see what happens.
A11: term_extension | B11: Term Extension | C11: financing | D11: 2 | E11: 3 | F11: add_deal_value | G11: 0.1267 | H11: 0 | I11: 0 | K11: 0 | L11: 0 | M11: 0.1733 | N11: common | P11: =$G11*30000*Assumptions!$B$15 -> 6271.65 | Q11: Ninety-six months is basically a mortgage with cupholders.
A12: doc_fee | B12: Doc Fee | C12: financing | D12: 0 | E12: 4 | F12: add_deal_value | G12: 0.03 | H12: 0 | I12: 0 | K12: 0 | L12: 0 | M12: 0.0433 | N12: common | P12: =$G12*30000*Assumptions!$B$15 -> 1485 | Q12: A fee for processing the paperwork that creates the fee.
A13: build_rapport | B13: Build Rapport | C13: none | D13: 1 | E13: 0 | F13: gain_shield | G13: 0 | H13: 0 | I13: 10 | K13: 0 | L13: 0 | M13: 14 | N13: starter | O13: YES | P13: =$G13*30000*Assumptions!$B$15 -> 0 | Q13: Your kid plays travel soccer? MY kid plays travel soccer.
A14: small_talk | B14: Small Talk | C14: none | D14: 0 | E14: 0 | F14: gain_shield | G14: 0 | H14: 0 | I14: 4 | K14: 0 | L14: 0 | M14: 6 | N14: starter | O14: YES | P14: =$G14*30000*Assumptions!$B$15 -> 0 | Q14: This weather, right? Anyway. About the financing.
A15: empathize | B15: Empathize | C15: protection | D15: 1 | E15: 0 | F15: gain_shield | G15: 0 | H15: 0.1 | I15: 6 | K15: 0 | L15: 0 | M15: 9 | N15: common | P15: =$G15*30000*Assumptions!$B$15 -> 0 | Q15: I hear you. I'm on your side. I am paid on commission.
A16: appraise | B16: Appraise | C16: none | D16: 0 | E16: 0 | F16: reveal_hidden | G16: 0 | H16: 0 | I16: 0 | K16: 1 | L16: 0 | M16: 0 | N16: starter | P16: =$G16*30000*Assumptions!$B$15 -> 0 | Q16: Let me check with my manager. (I am going to get a coffee.)
A17: probe_needs | B17: Probe Needs | C17: any | D17: 1 | E17: 0 | F17: reduce_resistance | G17: 0 | H17: 0.2 | I17: 0 | K17: 0 | L17: 0 | M17: 0 | N17: common | O17: YES | P17: =$G17*30000*Assumptions!$B$15 -> 0 | Q17: So what's your commute like? Asking for entirely selfless reasons.
A18: bide_your_time | B18: Bide Your Time | C18: none | D18: 0 | E18: 0 | F18: carry_energy | G18: 0 | H18: 0 | I18: 0 | K18: 0 | L18: 0 | M18: 0 | N18: common | P18: =$G18*30000*Assumptions!$B$15 -> 0 | Q18: Silence. Let them fill it. They always fill it.
A19: test_drive | B19: Test Drive | C19: vehicle | D19: 1 | E19: 0 | F19: draw_cards | G19: 0 | H19: 0 | I19: 5 | K19: 2 | L19: 0 | M19: 0 | N19: common | P19: =$G19*30000*Assumptions!$B$15 -> 0 | Q19: Once they smell the interior, the deal is already closed.
A20: anchor_high | B20: Anchor High | C20: any | D20: 1 | E20: 2 | F20: buff_next | G20: 0 | H20: 0 | I20: 0 | K20: 0 | L20: 0.5 | M20: 0.8 | N20: uncommon | P20: =$G20*30000*Assumptions!$B$15 -> 0 | Q20: Let's start with the fully loaded model. No reason. Just vibes.
A21: close_hard | B21: Close Hard | C21: any | D21: 2 | E21: 8 | F21: add_deal_value | G21: 0.2 | H21: 0 | I21: 0 | K21: 0 | L21: 0 | M21: 0.2667 | N21: uncommon | P21: =$G21*30000*Assumptions!$B$15 -> 9900 | Q21: I can only hold this price until you leave the building.
A22: beat_the_quote | B22: Beat The Quote | C22: none | D22: 1 | E22: 0 | F22: counter_objection | G22: 0 | H22: 0 | I22: 4 | J22: competitor_quote | K22: 0 | L22: 0 | M22: 6 | N22: common | O22: YES | P22: =$G22*30000*Assumptions!$B$15 -> 0 | Q22: Bring me the written offer. They will never bring the written offer.
A23: justify_the_value | B23: Justify The Value | C23: none | D23: 1 | E23: 0 | F23: counter_objection | G23: 0 | H23: 0 | I23: 4 | J23: dont_need_extras | K23: 0 | L23: 0 | M23: 6 | N23: common | O23: YES | P23: =$G23*30000*Assumptions!$B$15 -> 0 | Q23: You don't need it. You deserve it. Different word, same invoice.
A24: create_urgency | B24: Create Urgency | C24: none | D24: 1 | E24: 0 | F24: counter_objection | G24: 0 | H24: 0 | I24: 3 | J24: talk_to_spouse | K24: 0 | L24: 0 | M24: 5 | N24: common | P24: =$G24*30000*Assumptions!$B$15 -> 0 | Q24: Another couple looked at this exact one this morning. Allegedly.
A25: reframe_the_rate | B25: Reframe The Rate | C25: none | D25: 1 | E25: 0 | F25: counter_objection | G25: 0 | H25: 0 | I25: 4 | J25: preapproved | K25: 0 | L25: 0 | M25: 6 | N25: common | P25: =$G25*30000*Assumptions!$B$15 -> 0 | Q25: Forget the rate. Look at the monthly. Only look at the monthly.
A27: 'Value @ $30k' is what the card is worth against a $30,000 customer at the current Card Value Scale - for intuition only. The model always uses the percentage.

Sheet Customers
A1: CUSTOMER ARCHETYPES - Family First is the M0 default (most representative)
A2: Difficulty must come from resistance, patience and objection pool - NOT from budget size. See m0/README.md.
A3: ID | B3: Name | C3: Budget | D3: Starting Patience | E3: Res. Vehicle | F3: Res. Protection | G3: Res. Financing | H3: Sale ($) | I3: Strong ($) | J3: Max Close ($) | K3: Objection 1 | L3: Objection 2 | M3: Objection 3 | N3: Trait | O3: Description
A4: budget_buyer | B4: Budget Buyer | C4: 18000 | D4: 48 | E4: 0.25 | F4: 0.35 | G4: 0.55 | H4: =$C4*Assumptions!$B$8 -> 10800 | I4: =$C4*Assumptions!$B$9 -> 14400 | J4: =$C4*Assumptions!$B$10 -> 18000 | K4: price_objection | L4: dont_need_extras | M4: talk_to_spouse | N4: Commuter | O4: Has a number. Has had that number since 2019. Will say the number forty times.
A5: family_first | B5: Family First | C5: 30000 | D5: 50 | E5: 0.3 | F5: 0.15 | G5: 0.4 | H5: =$C5*Assumptions!$B$8 -> 18000 | I5: =$C5*Assumptions!$B$9 -> 24000 | J5: =$C5*Assumptions!$B$10 -> 30000 | K5: dont_need_extras | L5: talk_to_spouse | M5: price_objection | N5: Young Child | O5: Will buy anything with the word 'safety' printed on it. Cannot be rushed.
A6: tech_enthusiast | B6: Tech Enthusiast | C6: 40000 | D6: 44 | E6: 0.1 | F6: 0.35 | G6: 0.35 | H6: =$C6*Assumptions!$B$8 -> 24000 | I6: =$C6*Assumptions!$B$9 -> 32000 | J6: =$C6*Assumptions!$B$10 -> 40000 | K6: competitor_quote | L6: talk_to_spouse | M6: preapproved | N6: Lease Prefers | O6: Wants the screen. Already configured it online. Will leave if bored.
A8: Resistance is the share of a card's face value the customer refuses in that lane. The three Objection columns are the pool they draw from each turn.

Sheet Encounter Sim
A1: ENCOUNTER SIM - play a negotiation by hand, against a customer that fights back
A2: Edit blue cells only: the customer in B3, the Objection column in the turn table, and Turn / Card ID / Target Lane in the play log.
A3: Customer | B3: Family First | C3: <- Budget Buyer, Family First, or Tech Enthusiast
A4: Budget | B4: =INDEX(Customers!$C$4:$C$6,MATCH($B$3,Customers!$B$4:$B$6,0)) -> 30000
A5: Sale (60%) | B5: =INDEX(Customers!$H$4:$H$6,MATCH($B$3,Customers!$B$4:$B$6,0)) -> 18000
A6: Strong Close (80%) | B6: =INDEX(Customers!$I$4:$I$6,MATCH($B$3,Customers!$B$4:$B$6,0)) -> 24000
A7: Max Close (100%) | B7: =INDEX(Customers!$J$4:$J$6,MATCH($B$3,Customers!$B$4:$B$6,0)) -> 30000
A8: Starting Patience | B8: =INDEX(Customers!$D$4:$D$6,MATCH($B$3,Customers!$B$4:$B$6,0)) -> 50
A9: Resistance - Vehicle | B9: =INDEX(Customers!$E$4:$E$6,MATCH($B$3,Customers!$B$4:$B$6,0)) -> 0.3
A10: Resistance - Protection | B10: =INDEX(Customers!$F$4:$F$6,MATCH($B$3,Customers!$B$4:$B$6,0)) -> 0.15
A11: Resistance - Financing | B11: =INDEX(Customers!$G$4:$G$6,MATCH($B$3,Customers!$B$4:$B$6,0)) -> 0.4
A12: Objection Pool | B12: =INDEX(Customers!$K$4:$K$6,MATCH($B$3,Customers!$B$4:$B$6,0))&" | "&INDEX(Customers!$L$4:$L$6,MATCH($B$3,Customers!$B$4:$B$6,0))&" | "&INDEX(Customers!$M$4:$M$6,MATCH($B$3,Customers!$B$4:$B$6,0)) -> dont_need_extras | talk_to_spouse | price_objection
A14: OUTCOME (best tier you could have closed at)
A15: Final Deal Value | B15: =MAX($AE$22:$AE$33) -> 30000
A16: % of Budget | B16: =IFERROR($B$15/$B$4,0) -> 1
A17: Result | B17: =IF($B$15>=$B$7,"MAX CLOSE - full commission + reward pick",IF($B$15>=$B$6,"STRONG CLOSE",IF($B$15>=$B$5,"SALE","NO DEAL - below threshold"))) -> MAX CLOSE - full commission + reward pick
A18: Commission | B18: =IF($B$15>=$B$7,$B$15*Assumptions!$B$11*Assumptions!$B$14,IF($B$15>=$B$6,$B$15*Assumptions!$B$11*Assumptions!$B$13,IF($B$15>=$B$5,$B$15*Assumptions!$B$11*Assumptions!$B$12,0))) -> 5400
A19: Walked? | B19: =IF(COUNTIF($X$22:$X$33,0)>0,"YES - they walked. Anything you had not banked is gone.","No") -> YES - they walked. Anything you had not banked is gone.
A21: Turn | B21: Objection | C21: Damage | D21: Rider Type | E21: Rider Lane | F21: Rider Amt | G21: Countered? | H21: Energy Avail | I21: Energy Spent | J21: Energy OK? | K21: Carry Next | L21: Res Veh | M21: Res Pro | N21: Res Fin | O21: Locked Lane | P21: Value Mult | Q21: Value Added | R21: Value Shaved | S21: Cumulative | T21: % Budget | U21: Patience Cost | V21: Shield | W21: Damage Taken | X21: Patience End | Y21: ResRed Veh | Z21: ResRed Pro | AA21: ResRed Fin | AB21: Buff Gen | AC21: Energy Drain Next | AD21: Status | AE21: Closeable
A22: 1 | B22: talk_to_spouse | C22: =IFERROR(INDEX(Objections!$C$4:$C$8,MATCH($B22,Objections!$A$4:$A$8,0)),0)*(1+Assumptions!$B$16*($A22-1)) -> 4 | D22: =IFERROR(INDEX(Objections!$D$4:$D$8,MATCH($B22,Objections!$A$4:$A$8,0)),"") -> drain_energy | E22: =IFERROR(INDEX(Objections!$E$4:$E$8,MATCH($B22,Objections!$A$4:$A$8,0)),"") -> - | F22: =IFERROR(INDEX(Objections!$F$4:$F$8,MATCH($B22,Objections!$A$4:$A$8,0)),0) -> 1 | G22: =IF($B22="","-",IF(COUNTIFS($A$37:$A$76,$A22,$I$37:$I$76,$B22)>0,"YES","NO")) -> NO | H22: =Assumptions!$B$4 -> 3 | I22: =SUMIFS($F$37:$F$76,$A$37:$A$76,$A22) -> 2 | J22: =IF($I22>$H22,"OVER!","OK") -> OK | K22: =IF(COUNTIFS($A$37:$A$76,$A22,$B$37:$B$76,"bide_your_time")>0,MAX(0,$H22-$I22),0) -> 0 | L22: =$B$9 -> 0.3 | M22: =$B$10 -> 0.15 | N22: =$B$11 -> 0.4 | P22: 1 | Q22: =SUMIFS($Q$37:$Q$76,$A$37:$A$76,$A22) -> 2886.345 | R22: =IF(AND($D22="shave_value",$G22="NO"),0*$F22,0) -> 0 | S22: =MIN($B$4,MAX(0,0+$Q22-$R22)) -> 2886.345 | T22: =IFERROR($S22/$B$4,0) -> 0.0962115 | U22: =SUMIFS($G$37:$G$76,$A$37:$A$76,$A22) -> 0 | V22: =SUMIFS($H$37:$H$76,$A$37:$A$76,$A22) -> 4 | W22: =MAX(0,$C22-$V22) -> 0 | X22: =MAX(0,MIN($B$8,$B$8-$U22-$W22-IF($A22<=MAX($A$37:$A$76),Assumptions!$B$7,0))) -> 48 | Y22: =SUMIFS($J$37:$J$76,$A$37:$A$76,$A22,$E$37:$E$76,"vehicle") -> 0 | Z22: =SUMIFS($J$37:$J$76,$A$37:$A$76,$A22,$E$37:$E$76,"protection") -> 0 | AA22: =SUMIFS($J$37:$J$76,$A$37:$A$76,$A22,$E$37:$E$76,"financing") -> 0.2 | AB22: =SUMIFS($K$37:$K$76,$A$37:$A$76,$A22) -> 0 | AC22: =IF(AND($D22="drain_energy",$G22="NO"),$F22,0) -> 1 | AD22: =IF($A22>MAX($A$37:$A$76),"-",IF($S22>=$B$7,"MAX CLOSE",IF($S22>=$B$6,"STRONG CLOSE",IF($S22>=$B$5,"SALE AVAILABLE","BUILDING")))&IF($X22<=0," / THEY WALKED","")) -> BUILDING | AE22: =$S22 -> 2886.345
A23: =$A22+1 -> 2 | B23: dont_need_extras | C23: =IFERROR(INDEX(Objections!$C$4:$C$8,MATCH($B23,Objections!$A$4:$A$8,0)),0)*(1+Assumptions!$B$16*($A23-1)) -> 6.9 | D23: =IFERROR(INDEX(Objections!$D$4:$D$8,MATCH($B23,Objections!$A$4:$A$8,0)),"") -> lock_lane | E23: =IFERROR(INDEX(Objections!$E$4:$E$8,MATCH($B23,Objections!$A$4:$A$8,0)),"") -> protection | F23: =IFERROR(INDEX(Objections!$F$4:$F$8,MATCH($B23,Objections!$A$4:$A$8,0)),0) -> 0 | G23: =IF($B23="","-",IF(COUNTIFS($A$37:$A$76,$A23,$I$37:$I$76,$B23)>0,"YES","NO")) -> YES | H23: =MAX(0,Assumptions!$B$4+$K22-$AC22) -> 2 | I23: =SUMIFS($F$37:$F$76,$A$37:$A$76,$A23) -> 3 | J23: =IF($I23>$H23,"OVER!","OK") -> OVER! | K23: =IF(COUNTIFS($A$37:$A$76,$A23,$B$37:$B$76,"bide_your_time")>0,MAX(0,$H23-$I23),0) -> 0 | L23: =MAX(0,MIN(0.95,$L22-$Y22+IF(AND($D22="raise_resistance",$E22="vehicle",$G22="NO"),$F22,0))) -> 0.3 | M23: =MAX(0,MIN(0.95,$M22-$Z22+IF(AND($D22="raise_resistance",$E22="protection",$G22="NO"),$F22,0))) -> 0.15 | N23: =MAX(0,MIN(0.95,$N22-$AA22+IF(AND($D22="raise_resistance",$E22="financing",$G22="NO"),$F22,0))) -> 0.2 | O23: =IF(AND($D22="lock_lane",$G22="NO"),$E22,"") | P23: =1+$AB22 -> 1 | Q23: =SUMIFS($Q$37:$Q$76,$A$37:$A$76,$A23) -> 5776.155 | R23: =IF(AND($D23="shave_value",$G23="NO"),$S22*$F23,0) -> 0 | S23: =MIN($B$4,MAX(0,$S22+$Q23-$R23)) -> 8662.5 | T23: =IFERROR($S23/$B$4,0) -> 0.28875 | U23: =SUMIFS($G$37:$G$76,$A$37:$A$76,$A23) -> 3 | V23: =SUMIFS($H$37:$H$76,$A$37:$A$76,$A23) -> 4 | W23: =MAX(0,$C23-$V23) -> 2.9 | X23: =MAX(0,MIN($B$8,$X22-$U23-$W23-IF($A23<=MAX($A$37:$A$76),Assumptions!$B$7,0))) -> 40.1 | Y23: =SUMIFS($J$37:$J$76,$A$37:$A$76,$A23,$E$37:$E$76,"vehicle") -> 0 | Z23: =SUMIFS($J$37:$J$76,$A$37:$A$76,$A23,$E$37:$E$76,"protection") -> 0 | AA23: =SUMIFS($J$37:$J$76,$A$37:$A$76,$A23,$E$37:$E$76,"financing") -> 0 | AB23: =SUMIFS($K$37:$K$76,$A$37:$A$76,$A23) -> 0 | AC23: =IF(AND($D23="drain_energy",$G23="NO"),$F23,0) -> 0 | AD23: =IF(OR($A23>MAX($A$37:$A$76),$X22<=0),"-",IF($S23>=$B$7,"MAX CLOSE",IF($S23>=$B$6,"STRONG CLOSE",IF($S23>=$B$5,"SALE AVAILABLE","BUILDING")))&IF($X23<=0," / THEY WALKED","")) -> BUILDING | AE23: =IF($X22>0,$S23,0) -> 8662.5
A24: =$A23+1 -> 3 | B24: price_objection | C24: =IFERROR(INDEX(Objections!$C$4:$C$8,MATCH($B24,Objections!$A$4:$A$8,0)),0)*(1+Assumptions!$B$16*($A24-1)) -> 13 | D24: =IFERROR(INDEX(Objections!$D$4:$D$8,MATCH($B24,Objections!$A$4:$A$8,0)),"") -> - | E24: =IFERROR(INDEX(Objections!$E$4:$E$8,MATCH($B24,Objections!$A$4:$A$8,0)),"") -> - | F24: =IFERROR(INDEX(Objections!$F$4:$F$8,MATCH($B24,Objections!$A$4:$A$8,0)),0) -> 0 | G24: =IF($B24="","-",IF(COUNTIFS($A$37:$A$76,$A24,$I$37:$I$76,$B24)>0,"YES","NO")) -> NO | H24: =MAX(0,Assumptions!$B$4+$K23-$AC23) -> 3 | I24: =SUMIFS($F$37:$F$76,$A$37:$A$76,$A24) -> 3 | J24: =IF($I24>$H24,"OVER!","OK") -> OK | K24: =IF(COUNTIFS($A$37:$A$76,$A24,$B$37:$B$76,"bide_your_time")>0,MAX(0,$H24-$I24),0) -> 0 | L24: =MAX(0,MIN(0.95,$L23-$Y23+IF(AND($D23="raise_resistance",$E23="vehicle",$G23="NO"),$F23,0))) -> 0.3 | M24: =MAX(0,MIN(0.95,$M23-$Z23+IF(AND($D23="raise_resistance",$E23="protection",$G23="NO"),$F23,0))) -> 0.15 | N24: =MAX(0,MIN(0.95,$N23-$AA23+IF(AND($D23="raise_resistance",$E23="financing",$G23="NO"),$F23,0))) -> 0.2 | O24: =IF(AND($D23="lock_lane",$G23="NO"),$E23,"") | P24: =1+$AB23 -> 1 | Q24: =SUMIFS($Q$37:$Q$76,$A$37:$A$76,$A24) -> 5608.5975 | R24: =IF(AND($D24="shave_value",$G24="NO"),$S23*$F24,0) -> 0 | S24: =MIN($B$4,MAX(0,$S23+$Q24-$R24)) -> 14271.097 | T24: =IFERROR($S24/$B$4,0) -> 0.47570325 | U24: =SUMIFS($G$37:$G$76,$A$37:$A$76,$A24) -> 4 | V24: =SUMIFS($H$37:$H$76,$A$37:$A$76,$A24) -> 10 | W24: =MAX(0,$C24-$V24) -> 3 | X24: =MAX(0,MIN($B$8,$X23-$U24-$W24-IF($A24<=MAX($A$37:$A$76),Assumptions!$B$7,0))) -> 31.1 | Y24: =SUMIFS($J$37:$J$76,$A$37:$A$76,$A24,$E$37:$E$76,"vehicle") -> 0 | Z24: =SUMIFS($J$37:$J$76,$A$37:$A$76,$A24,$E$37:$E$76,"protection") -> 0 | AA24: =SUMIFS($J$37:$J$76,$A$37:$A$76,$A24,$E$37:$E$76,"financing") -> 0 | AB24: =SUMIFS($K$37:$K$76,$A$37:$A$76,$A24) -> 0 | AC24: =IF(AND($D24="drain_energy",$G24="NO"),$F24,0) -> 0 | AD24: =IF(OR($A24>MAX($A$37:$A$76),$X23<=0),"-",IF($S24>=$B$7,"MAX CLOSE",IF($S24>=$B$6,"STRONG CLOSE",IF($S24>=$B$5,"SALE AVAILABLE","BUILDING")))&IF($X24<=0," / THEY WALKED","")) -> BUILDING | AE24: =IF($X23>0,$S24,0) -> 14271.097
A25: =$A24+1 -> 4 | B25: dont_need_extras | C25: =IFERROR(INDEX(Objections!$C$4:$C$8,MATCH($B25,Objections!$A$4:$A$8,0)),0)*(1+Assumptions!$B$16*($A25-1)) -> 8.7 | D25: =IFERROR(INDEX(Objections!$D$4:$D$8,MATCH($B25,Objections!$A$4:$A$8,0)),"") -> lock_lane | E25: =IFERROR(INDEX(Objections!$E$4:$E$8,MATCH($B25,Objections!$A$4:$A$8,0)),"") -> protection | F25: =IFERROR(INDEX(Objections!$F$4:$F$8,MATCH($B25,Objections!$A$4:$A$8,0)),0) -> 0 | G25: =IF($B25="","-",IF(COUNTIFS($A$37:$A$76,$A25,$I$37:$I$76,$B25)>0,"YES","NO")) -> YES | H25: =MAX(0,Assumptions!$B$4+$K24-$AC24) -> 3 | I25: =SUMIFS($F$37:$F$76,$A$37:$A$76,$A25) -> 2 | J25: =IF($I25>$H25,"OVER!","OK") -> OK | K25: =IF(COUNTIFS($A$37:$A$76,$A25,$B$37:$B$76,"bide_your_time")>0,MAX(0,$H25-$I25),0) -> 0 | L25: =MAX(0,MIN(0.95,$L24-$Y24+IF(AND($D24="raise_resistance",$E24="vehicle",$G24="NO"),$F24,0))) -> 0.3 | M25: =MAX(0,MIN(0.95,$M24-$Z24+IF(AND($D24="raise_resistance",$E24="protection",$G24="NO"),$F24,0))) -> 0.15 | N25: =MAX(0,MIN(0.95,$N24-$AA24+IF(AND($D24="raise_resistance",$E24="financing",$G24="NO"),$F24,0))) -> 0.2 | O25: =IF(AND($D24="lock_lane",$G24="NO"),$E24,"") | P25: =1+$AB24 -> 1 | Q25: =SUMIFS($Q$37:$Q$76,$A$37:$A$76,$A25) -> 2641.32 | R25: =IF(AND($D25="shave_value",$G25="NO"),$S24*$F25,0) -> 0 | S25: =MIN($B$4,MAX(0,$S24+$Q25-$R25)) -> 16912.417 | T25: =IFERROR($S25/$B$4,0) -> 0.56374725 | U25: =SUMIFS($G$37:$G$76,$A$37:$A$76,$A25) -> 5 | V25: =SUMIFS($H$37:$H$76,$A$37:$A$76,$A25) -> 4 | W25: =MAX(0,$C25-$V25) -> 4.7 | X25: =MAX(0,MIN($B$8,$X24-$U25-$W25-IF($A25<=MAX($A$37:$A$76),Assumptions!$B$7,0))) -> 19.4 | Y25: =SUMIFS($J$37:$J$76,$A$37:$A$76,$A25,$E$37:$E$76,"vehicle") -> 0 | Z25: =SUMIFS($J$37:$J$76,$A$37:$A$76,$A25,$E$37:$E$76,"protection") -> 0 | AA25: =SUMIFS($J$37:$J$76,$A$37:$A$76,$A25,$E$37:$E$76,"financing") -> 0 | AB25: =SUMIFS($K$37:$K$76,$A$37:$A$76,$A25) -> 0 | AC25: =IF(AND($D25="drain_energy",$G25="NO"),$F25,0) -> 0 | AD25: =IF(OR($A25>MAX($A$37:$A$76),$X24<=0),"-",IF($S25>=$B$7,"MAX CLOSE",IF($S25>=$B$6,"STRONG CLOSE",IF($S25>=$B$5,"SALE AVAILABLE","BUILDING")))&IF($X25<=0," / THEY WALKED","")) -> BUILDING | AE25: =IF($X24>0,$S25,0) -> 16912.417
A26: =$A25+1 -> 5 | B26: price_objection | C26: =IFERROR(INDEX(Objections!$C$4:$C$8,MATCH($B26,Objections!$A$4:$A$8,0)),0)*(1+Assumptions!$B$16*($A26-1)) -> 16 | D26: =IFERROR(INDEX(Objections!$D$4:$D$8,MATCH($B26,Objections!$A$4:$A$8,0)),"") -> - | E26: =IFERROR(INDEX(Objections!$E$4:$E$8,MATCH($B26,Objections!$A$4:$A$8,0)),"") -> - | F26: =IFERROR(INDEX(Objections!$F$4:$F$8,MATCH($B26,Objections!$A$4:$A$8,0)),0) -> 0 | G26: =IF($B26="","-",IF(COUNTIFS($A$37:$A$76,$A26,$I$37:$I$76,$B26)>0,"YES","NO")) -> NO | H26: =MAX(0,Assumptions!$B$4+$K25-$AC25) -> 3 | I26: =SUMIFS($F$37:$F$76,$A$37:$A$76,$A26) -> 3 | J26: =IF($I26>$H26,"OVER!","OK") -> OK | K26: =IF(COUNTIFS($A$37:$A$76,$A26,$B$37:$B$76,"bide_your_time")>0,MAX(0,$H26-$I26),0) -> 0 | L26: =MAX(0,MIN(0.95,$L25-$Y25+IF(AND($D25="raise_resistance",$E25="vehicle",$G25="NO"),$F25,0))) -> 0.3 | M26: =MAX(0,MIN(0.95,$M25-$Z25+IF(AND($D25="raise_resistance",$E25="protection",$G25="NO"),$F25,0))) -> 0.15 | N26: =MAX(0,MIN(0.95,$N25-$AA25+IF(AND($D25="raise_resistance",$E25="financing",$G25="NO"),$F25,0))) -> 0.2 | O26: =IF(AND($D25="lock_lane",$G25="NO"),$E25,"") | P26: =1+$AB25 -> 1 | Q26: =SUMIFS($Q$37:$Q$76,$A$37:$A$76,$A26) -> 5017.32 | R26: =IF(AND($D26="shave_value",$G26="NO"),$S25*$F26,0) -> 0 | S26: =MIN($B$4,MAX(0,$S25+$Q26-$R26)) -> 21929.737 | T26: =IFERROR($S26/$B$4,0) -> 0.73099125 | U26: =SUMIFS($G$37:$G$76,$A$37:$A$76,$A26) -> 3 | V26: =SUMIFS($H$37:$H$76,$A$37:$A$76,$A26) -> 10 | W26: =MAX(0,$C26-$V26) -> 6 | X26: =MAX(0,MIN($B$8,$X25-$U26-$W26-IF($A26<=MAX($A$37:$A$76),Assumptions!$B$7,0))) -> 8.4 | Y26: =SUMIFS($J$37:$J$76,$A$37:$A$76,$A26,$E$37:$E$76,"vehicle") -> 0 | Z26: =SUMIFS($J$37:$J$76,$A$37:$A$76,$A26,$E$37:$E$76,"protection") -> 0 | AA26: =SUMIFS($J$37:$J$76,$A$37:$A$76,$A26,$E$37:$E$76,"financing") -> 0 | AB26: =SUMIFS($K$37:$K$76,$A$37:$A$76,$A26) -> 0 | AC26: =IF(AND($D26="drain_energy",$G26="NO"),$F26,0) -> 0 | AD26: =IF(OR($A26>MAX($A$37:$A$76),$X25<=0),"-",IF($S26>=$B$7,"MAX CLOSE",IF($S26>=$B$6,"STRONG CLOSE",IF($S26>=$B$5,"SALE AVAILABLE","BUILDING")))&IF($X26<=0," / THEY WALKED","")) -> SALE AVAILABLE | AE26: =IF($X25>0,$S26,0) -> 21929.737
A27: =$A26+1 -> 6 | B27: talk_to_spouse | C27: =IFERROR(INDEX(Objections!$C$4:$C$8,MATCH($B27,Objections!$A$4:$A$8,0)),0)*(1+Assumptions!$B$16*($A27-1)) -> 7 | D27: =IFERROR(INDEX(Objections!$D$4:$D$8,MATCH($B27,Objections!$A$4:$A$8,0)),"") -> drain_energy | E27: =IFERROR(INDEX(Objections!$E$4:$E$8,MATCH($B27,Objections!$A$4:$A$8,0)),"") -> - | F27: =IFERROR(INDEX(Objections!$F$4:$F$8,MATCH($B27,Objections!$A$4:$A$8,0)),0) -> 1 | G27: =IF($B27="","-",IF(COUNTIFS($A$37:$A$76,$A27,$I$37:$I$76,$B27)>0,"YES","NO")) -> NO | H27: =MAX(0,Assumptions!$B$4+$K26-$AC26) -> 3 | I27: =SUMIFS($F$37:$F$76,$A$37:$A$76,$A27) -> 3 | J27: =IF($I27>$H27,"OVER!","OK") -> OK | K27: =IF(COUNTIFS($A$37:$A$76,$A27,$B$37:$B$76,"bide_your_time")>0,MAX(0,$H27-$I27),0) -> 0 | L27: =MAX(0,MIN(0.95,$L26-$Y26+IF(AND($D26="raise_resistance",$E26="vehicle",$G26="NO"),$F26,0))) -> 0.3 | M27: =MAX(0,MIN(0.95,$M26-$Z26+IF(AND($D26="raise_resistance",$E26="protection",$G26="NO"),$F26,0))) -> 0.15 | N27: =MAX(0,MIN(0.95,$N26-$AA26+IF(AND($D26="raise_resistance",$E26="financing",$G26="NO"),$F26,0))) -> 0.2 | O27: =IF(AND($D26="lock_lane",$G26="NO"),$E26,"") | P27: =1+$AB26 -> 1 | Q27: =SUMIFS($Q$37:$Q$76,$A$37:$A$76,$A27) -> 10014.097 | R27: =IF(AND($D27="shave_value",$G27="NO"),$S26*$F27,0) -> 0 | S27: =MIN($B$4,MAX(0,$S26+$Q27-$R27)) -> 30000 | T27: =IFERROR($S27/$B$4,0) -> 1 | U27: =SUMIFS($G$37:$G$76,$A$37:$A$76,$A27) -> 10 | V27: =SUMIFS($H$37:$H$76,$A$37:$A$76,$A27) -> 4 | W27: =MAX(0,$C27-$V27) -> 3 | X27: =MAX(0,MIN($B$8,$X26-$U27-$W27-IF($A27<=MAX($A$37:$A$76),Assumptions!$B$7,0))) -> 0 | Y27: =SUMIFS($J$37:$J$76,$A$37:$A$76,$A27,$E$37:$E$76,"vehicle") -> 0 | Z27: =SUMIFS($J$37:$J$76,$A$37:$A$76,$A27,$E$37:$E$76,"protection") -> 0 | AA27: =SUMIFS($J$37:$J$76,$A$37:$A$76,$A27,$E$37:$E$76,"financing") -> 0 | AB27: =SUMIFS($K$37:$K$76,$A$37:$A$76,$A27) -> 0 | AC27: =IF(AND($D27="drain_energy",$G27="NO"),$F27,0) -> 1 | AD27: =IF(OR($A27>MAX($A$37:$A$76),$X26<=0),"-",IF($S27>=$B$7,"MAX CLOSE",IF($S27>=$B$6,"STRONG CLOSE",IF($S27>=$B$5,"SALE AVAILABLE","BUILDING")))&IF($X27<=0," / THEY WALKED","")) -> MAX CLOSE / THEY WALKED | AE27: =IF($X26>0,$S27,0) -> 30000
A28: =$A27+1 -> 7 | C28: =IFERROR(INDEX(Objections!$C$4:$C$8,MATCH($B28,Objections!$A$4:$A$8,0)),0)*(1+Assumptions!$B$16*($A28-1)) -> 0 | D28: =IFERROR(INDEX(Objections!$D$4:$D$8,MATCH($B28,Objections!$A$4:$A$8,0)),"") | E28: =IFERROR(INDEX(Objections!$E$4:$E$8,MATCH($B28,Objections!$A$4:$A$8,0)),"") | F28: =IFERROR(INDEX(Objections!$F$4:$F$8,MATCH($B28,Objections!$A$4:$A$8,0)),0) -> 0 | G28: =IF($B28="","-",IF(COUNTIFS($A$37:$A$76,$A28,$I$37:$I$76,$B28)>0,"YES","NO")) -> - | H28: =MAX(0,Assumptions!$B$4+$K27-$AC27) -> 2 | I28: =SUMIFS($F$37:$F$76,$A$37:$A$76,$A28) -> 0 | J28: =IF($I28>$H28,"OVER!","OK") -> OK | K28: =IF(COUNTIFS($A$37:$A$76,$A28,$B$37:$B$76,"bide_your_time")>0,MAX(0,$H28-$I28),0) -> 0 | L28: =MAX(0,MIN(0.95,$L27-$Y27+IF(AND($D27="raise_resistance",$E27="vehicle",$G27="NO"),$F27,0))) -> 0.3 | M28: =MAX(0,MIN(0.95,$M27-$Z27+IF(AND($D27="raise_resistance",$E27="protection",$G27="NO"),$F27,0))) -> 0.15 | N28: =MAX(0,MIN(0.95,$N27-$AA27+IF(AND($D27="raise_resistance",$E27="financing",$G27="NO"),$F27,0))) -> 0.2 | O28: =IF(AND($D27="lock_lane",$G27="NO"),$E27,"") | P28: =1+$AB27 -> 1 | Q28: =SUMIFS($Q$37:$Q$76,$A$37:$A$76,$A28) -> 0 | R28: =IF(AND($D28="shave_value",$G28="NO"),$S27*$F28,0) -> 0 | S28: =MIN($B$4,MAX(0,$S27+$Q28-$R28)) -> 30000 | T28: =IFERROR($S28/$B$4,0) -> 1 | U28: =SUMIFS($G$37:$G$76,$A$37:$A$76,$A28) -> 0 | V28: =SUMIFS($H$37:$H$76,$A$37:$A$76,$A28) -> 0 | W28: =MAX(0,$C28-$V28) -> 0 | X28: =MAX(0,MIN($B$8,$X27-$U28-$W28-IF($A28<=MAX($A$37:$A$76),Assumptions!$B$7,0))) -> 0 | Y28: =SUMIFS($J$37:$J$76,$A$37:$A$76,$A28,$E$37:$E$76,"vehicle") -> 0 | Z28: =SUMIFS($J$37:$J$76,$A$37:$A$76,$A28,$E$37:$E$76,"protection") -> 0 | AA28: =SUMIFS($J$37:$J$76,$A$37:$A$76,$A28,$E$37:$E$76,"financing") -> 0 | AB28: =SUMIFS($K$37:$K$76,$A$37:$A$76,$A28) -> 0 | AC28: =IF(AND($D28="drain_energy",$G28="NO"),$F28,0) -> 0 | AD28: =IF(OR($A28>MAX($A$37:$A$76),$X27<=0),"-",IF($S28>=$B$7,"MAX CLOSE",IF($S28>=$B$6,"STRONG CLOSE",IF($S28>=$B$5,"SALE AVAILABLE","BUILDING")))&IF($X28<=0," / THEY WALKED","")) -> - | AE28: =IF($X27>0,$S28,0) -> 0
A29: =$A28+1 -> 8 | C29: =IFERROR(INDEX(Objections!$C$4:$C$8,MATCH($B29,Objections!$A$4:$A$8,0)),0)*(1+Assumptions!$B$16*($A29-1)) -> 0 | D29: =IFERROR(INDEX(Objections!$D$4:$D$8,MATCH($B29,Objections!$A$4:$A$8,0)),"") | E29: =IFERROR(INDEX(Objections!$E$4:$E$8,MATCH($B29,Objections!$A$4:$A$8,0)),"") | F29: =IFERROR(INDEX(Objections!$F$4:$F$8,MATCH($B29,Objections!$A$4:$A$8,0)),0) -> 0 | G29: =IF($B29="","-",IF(COUNTIFS($A$37:$A$76,$A29,$I$37:$I$76,$B29)>0,"YES","NO")) -> - | H29: =MAX(0,Assumptions!$B$4+$K28-$AC28) -> 3 | I29: =SUMIFS($F$37:$F$76,$A$37:$A$76,$A29) -> 0 | J29: =IF($I29>$H29,"OVER!","OK") -> OK | K29: =IF(COUNTIFS($A$37:$A$76,$A29,$B$37:$B$76,"bide_your_time")>0,MAX(0,$H29-$I29),0) -> 0 | L29: =MAX(0,MIN(0.95,$L28-$Y28+IF(AND($D28="raise_resistance",$E28="vehicle",$G28="NO"),$F28,0))) -> 0.3 | M29: =MAX(0,MIN(0.95,$M28-$Z28+IF(AND($D28="raise_resistance",$E28="protection",$G28="NO"),$F28,0))) -> 0.15 | N29: =MAX(0,MIN(0.95,$N28-$AA28+IF(AND($D28="raise_resistance",$E28="financing",$G28="NO"),$F28,0))) -> 0.2 | O29: =IF(AND($D28="lock_lane",$G28="NO"),$E28,"") | P29: =1+$AB28 -> 1 | Q29: =SUMIFS($Q$37:$Q$76,$A$37:$A$76,$A29) -> 0 | R29: =IF(AND($D29="shave_value",$G29="NO"),$S28*$F29,0) -> 0 | S29: =MIN($B$4,MAX(0,$S28+$Q29-$R29)) -> 30000 | T29: =IFERROR($S29/$B$4,0) -> 1 | U29: =SUMIFS($G$37:$G$76,$A$37:$A$76,$A29) -> 0 | V29: =SUMIFS($H$37:$H$76,$A$37:$A$76,$A29) -> 0 | W29: =MAX(0,$C29-$V29) -> 0 | X29: =MAX(0,MIN($B$8,$X28-$U29-$W29-IF($A29<=MAX($A$37:$A$76),Assumptions!$B$7,0))) -> 0 | Y29: =SUMIFS($J$37:$J$76,$A$37:$A$76,$A29,$E$37:$E$76,"vehicle") -> 0 | Z29: =SUMIFS($J$37:$J$76,$A$37:$A$76,$A29,$E$37:$E$76,"protection") -> 0 | AA29: =SUMIFS($J$37:$J$76,$A$37:$A$76,$A29,$E$37:$E$76,"financing") -> 0 | AB29: =SUMIFS($K$37:$K$76,$A$37:$A$76,$A29) -> 0 | AC29: =IF(AND($D29="drain_energy",$G29="NO"),$F29,0) -> 0 | AD29: =IF(OR($A29>MAX($A$37:$A$76),$X28<=0),"-",IF($S29>=$B$7,"MAX CLOSE",IF($S29>=$B$6,"STRONG CLOSE",IF($S29>=$B$5,"SALE AVAILABLE","BUILDING")))&IF($X29<=0," / THEY WALKED","")) -> - | AE29: =IF($X28>0,$S29,0) -> 0
A30: =$A29+1 -> 9 | C30: =IFERROR(INDEX(Objections!$C$4:$C$8,MATCH($B30,Objections!$A$4:$A$8,0)),0)*(1+Assumptions!$B$16*($A30-1)) -> 0 | D30: =IFERROR(INDEX(Objections!$D$4:$D$8,MATCH($B30,Objections!$A$4:$A$8,0)),"") | E30: =IFERROR(INDEX(Objections!$E$4:$E$8,MATCH($B30,Objections!$A$4:$A$8,0)),"") | F30: =IFERROR(INDEX(Objections!$F$4:$F$8,MATCH($B30,Objections!$A$4:$A$8,0)),0) -> 0 | G30: =IF($B30="","-",IF(COUNTIFS($A$37:$A$76,$A30,$I$37:$I$76,$B30)>0,"YES","NO")) -> - | H30: =MAX(0,Assumptions!$B$4+$K29-$AC29) -> 3 | I30: =SUMIFS($F$37:$F$76,$A$37:$A$76,$A30) -> 0 | J30: =IF($I30>$H30,"OVER!","OK") -> OK | K30: =IF(COUNTIFS($A$37:$A$76,$A30,$B$37:$B$76,"bide_your_time")>0,MAX(0,$H30-$I30),0) -> 0 | L30: =MAX(0,MIN(0.95,$L29-$Y29+IF(AND($D29="raise_resistance",$E29="vehicle",$G29="NO"),$F29,0))) -> 0.3 | M30: =MAX(0,MIN(0.95,$M29-$Z29+IF(AND($D29="raise_resistance",$E29="protection",$G29="NO"),$F29,0))) -> 0.15 | N30: =MAX(0,MIN(0.95,$N29-$AA29+IF(AND($D29="raise_resistance",$E29="financing",$G29="NO"),$F29,0))) -> 0.2 | O30: =IF(AND($D29="lock_lane",$G29="NO"),$E29,"") | P30: =1+$AB29 -> 1 | Q30: =SUMIFS($Q$37:$Q$76,$A$37:$A$76,$A30) -> 0 | R30: =IF(AND($D30="shave_value",$G30="NO"),$S29*$F30,0) -> 0 | S30: =MIN($B$4,MAX(0,$S29+$Q30-$R30)) -> 30000 | T30: =IFERROR($S30/$B$4,0) -> 1 | U30: =SUMIFS($G$37:$G$76,$A$37:$A$76,$A30) -> 0 | V30: =SUMIFS($H$37:$H$76,$A$37:$A$76,$A30) -> 0 | W30: =MAX(0,$C30-$V30) -> 0 | X30: =MAX(0,MIN($B$8,$X29-$U30-$W30-IF($A30<=MAX($A$37:$A$76),Assumptions!$B$7,0))) -> 0 | Y30: =SUMIFS($J$37:$J$76,$A$37:$A$76,$A30,$E$37:$E$76,"vehicle") -> 0 | Z30: =SUMIFS($J$37:$J$76,$A$37:$A$76,$A30,$E$37:$E$76,"protection") -> 0 | AA30: =SUMIFS($J$37:$J$76,$A$37:$A$76,$A30,$E$37:$E$76,"financing") -> 0 | AB30: =SUMIFS($K$37:$K$76,$A$37:$A$76,$A30) -> 0 | AC30: =IF(AND($D30="drain_energy",$G30="NO"),$F30,0) -> 0 | AD30: =IF(OR($A30>MAX($A$37:$A$76),$X29<=0),"-",IF($S30>=$B$7,"MAX CLOSE",IF($S30>=$B$6,"STRONG CLOSE",IF($S30>=$B$5,"SALE AVAILABLE","BUILDING")))&IF($X30<=0," / THEY WALKED","")) -> - | AE30: =IF($X29>0,$S30,0) -> 0
A31: =$A30+1 -> 10 | C31: =IFERROR(INDEX(Objections!$C$4:$C$8,MATCH($B31,Objections!$A$4:$A$8,0)),0)*(1+Assumptions!$B$16*($A31-1)) -> 0 | D31: =IFERROR(INDEX(Objections!$D$4:$D$8,MATCH($B31,Objections!$A$4:$A$8,0)),"") | E31: =IFERROR(INDEX(Objections!$E$4:$E$8,MATCH($B31,Objections!$A$4:$A$8,0)),"") | F31: =IFERROR(INDEX(Objections!$F$4:$F$8,MATCH($B31,Objections!$A$4:$A$8,0)),0) -> 0 | G31: =IF($B31="","-",IF(COUNTIFS($A$37:$A$76,$A31,$I$37:$I$76,$B31)>0,"YES","NO")) -> - | H31: =MAX(0,Assumptions!$B$4+$K30-$AC30) -> 3 | I31: =SUMIFS($F$37:$F$76,$A$37:$A$76,$A31) -> 0 | J31: =IF($I31>$H31,"OVER!","OK") -> OK | K31: =IF(COUNTIFS($A$37:$A$76,$A31,$B$37:$B$76,"bide_your_time")>0,MAX(0,$H31-$I31),0) -> 0 | L31: =MAX(0,MIN(0.95,$L30-$Y30+IF(AND($D30="raise_resistance",$E30="vehicle",$G30="NO"),$F30,0))) -> 0.3 | M31: =MAX(0,MIN(0.95,$M30-$Z30+IF(AND($D30="raise_resistance",$E30="protection",$G30="NO"),$F30,0))) -> 0.15 | N31: =MAX(0,MIN(0.95,$N30-$AA30+IF(AND($D30="raise_resistance",$E30="financing",$G30="NO"),$F30,0))) -> 0.2 | O31: =IF(AND($D30="lock_lane",$G30="NO"),$E30,"") | P31: =1+$AB30 -> 1 | Q31: =SUMIFS($Q$37:$Q$76,$A$37:$A$76,$A31) -> 0 | R31: =IF(AND($D31="shave_value",$G31="NO"),$S30*$F31,0) -> 0 | S31: =MIN($B$4,MAX(0,$S30+$Q31-$R31)) -> 30000 | T31: =IFERROR($S31/$B$4,0) -> 1 | U31: =SUMIFS($G$37:$G$76,$A$37:$A$76,$A31) -> 0 | V31: =SUMIFS($H$37:$H$76,$A$37:$A$76,$A31) -> 0 | W31: =MAX(0,$C31-$V31) -> 0 | X31: =MAX(0,MIN($B$8,$X30-$U31-$W31-IF($A31<=MAX($A$37:$A$76),Assumptions!$B$7,0))) -> 0 | Y31: =SUMIFS($J$37:$J$76,$A$37:$A$76,$A31,$E$37:$E$76,"vehicle") -> 0 | Z31: =SUMIFS($J$37:$J$76,$A$37:$A$76,$A31,$E$37:$E$76,"protection") -> 0 | AA31: =SUMIFS($J$37:$J$76,$A$37:$A$76,$A31,$E$37:$E$76,"financing") -> 0 | AB31: =SUMIFS($K$37:$K$76,$A$37:$A$76,$A31) -> 0 | AC31: =IF(AND($D31="drain_energy",$G31="NO"),$F31,0) -> 0 | AD31: =IF(OR($A31>MAX($A$37:$A$76),$X30<=0),"-",IF($S31>=$B$7,"MAX CLOSE",IF($S31>=$B$6,"STRONG CLOSE",IF($S31>=$B$5,"SALE AVAILABLE","BUILDING")))&IF($X31<=0," / THEY WALKED","")) -> - | AE31: =IF($X30>0,$S31,0) -> 0
A32: =$A31+1 -> 11 | C32: =IFERROR(INDEX(Objections!$C$4:$C$8,MATCH($B32,Objections!$A$4:$A$8,0)),0)*(1+Assumptions!$B$16*($A32-1)) -> 0 | D32: =IFERROR(INDEX(Objections!$D$4:$D$8,MATCH($B32,Objections!$A$4:$A$8,0)),"") | E32: =IFERROR(INDEX(Objections!$E$4:$E$8,MATCH($B32,Objections!$A$4:$A$8,0)),"") | F32: =IFERROR(INDEX(Objections!$F$4:$F$8,MATCH($B32,Objections!$A$4:$A$8,0)),0) -> 0 | G32: =IF($B32="","-",IF(COUNTIFS($A$37:$A$76,$A32,$I$37:$I$76,$B32)>0,"YES","NO")) -> - | H32: =MAX(0,Assumptions!$B$4+$K31-$AC31) -> 3 | I32: =SUMIFS($F$37:$F$76,$A$37:$A$76,$A32) -> 0 | J32: =IF($I32>$H32,"OVER!","OK") -> OK | K32: =IF(COUNTIFS($A$37:$A$76,$A32,$B$37:$B$76,"bide_your_time")>0,MAX(0,$H32-$I32),0) -> 0 | L32: =MAX(0,MIN(0.95,$L31-$Y31+IF(AND($D31="raise_resistance",$E31="vehicle",$G31="NO"),$F31,0))) -> 0.3 | M32: =MAX(0,MIN(0.95,$M31-$Z31+IF(AND($D31="raise_resistance",$E31="protection",$G31="NO"),$F31,0))) -> 0.15 | N32: =MAX(0,MIN(0.95,$N31-$AA31+IF(AND($D31="raise_resistance",$E31="financing",$G31="NO"),$F31,0))) -> 0.2 | O32: =IF(AND($D31="lock_lane",$G31="NO"),$E31,"") | P32: =1+$AB31 -> 1 | Q32: =SUMIFS($Q$37:$Q$76,$A$37:$A$76,$A32) -> 0 | R32: =IF(AND($D32="shave_value",$G32="NO"),$S31*$F32,0) -> 0 | S32: =MIN($B$4,MAX(0,$S31+$Q32-$R32)) -> 30000 | T32: =IFERROR($S32/$B$4,0) -> 1 | U32: =SUMIFS($G$37:$G$76,$A$37:$A$76,$A32) -> 0 | V32: =SUMIFS($H$37:$H$76,$A$37:$A$76,$A32) -> 0 | W32: =MAX(0,$C32-$V32) -> 0 | X32: =MAX(0,MIN($B$8,$X31-$U32-$W32-IF($A32<=MAX($A$37:$A$76),Assumptions!$B$7,0))) -> 0 | Y32: =SUMIFS($J$37:$J$76,$A$37:$A$76,$A32,$E$37:$E$76,"vehicle") -> 0 | Z32: =SUMIFS($J$37:$J$76,$A$37:$A$76,$A32,$E$37:$E$76,"protection") -> 0 | AA32: =SUMIFS($J$37:$J$76,$A$37:$A$76,$A32,$E$37:$E$76,"financing") -> 0 | AB32: =SUMIFS($K$37:$K$76,$A$37:$A$76,$A32) -> 0 | AC32: =IF(AND($D32="drain_energy",$G32="NO"),$F32,0) -> 0 | AD32: =IF(OR($A32>MAX($A$37:$A$76),$X31<=0),"-",IF($S32>=$B$7,"MAX CLOSE",IF($S32>=$B$6,"STRONG CLOSE",IF($S32>=$B$5,"SALE AVAILABLE","BUILDING")))&IF($X32<=0," / THEY WALKED","")) -> - | AE32: =IF($X31>0,$S32,0) -> 0
A33: =$A32+1 -> 12 | C33: =IFERROR(INDEX(Objections!$C$4:$C$8,MATCH($B33,Objections!$A$4:$A$8,0)),0)*(1+Assumptions!$B$16*($A33-1)) -> 0 | D33: =IFERROR(INDEX(Objections!$D$4:$D$8,MATCH($B33,Objections!$A$4:$A$8,0)),"") | E33: =IFERROR(INDEX(Objections!$E$4:$E$8,MATCH($B33,Objections!$A$4:$A$8,0)),"") | F33: =IFERROR(INDEX(Objections!$F$4:$F$8,MATCH($B33,Objections!$A$4:$A$8,0)),0) -> 0 | G33: =IF($B33="","-",IF(COUNTIFS($A$37:$A$76,$A33,$I$37:$I$76,$B33)>0,"YES","NO")) -> - | H33: =MAX(0,Assumptions!$B$4+$K32-$AC32) -> 3 | I33: =SUMIFS($F$37:$F$76,$A$37:$A$76,$A33) -> 0 | J33: =IF($I33>$H33,"OVER!","OK") -> OK | K33: =IF(COUNTIFS($A$37:$A$76,$A33,$B$37:$B$76,"bide_your_time")>0,MAX(0,$H33-$I33),0) -> 0 | L33: =MAX(0,MIN(0.95,$L32-$Y32+IF(AND($D32="raise_resistance",$E32="vehicle",$G32="NO"),$F32,0))) -> 0.3 | M33: =MAX(0,MIN(0.95,$M32-$Z32+IF(AND($D32="raise_resistance",$E32="protection",$G32="NO"),$F32,0))) -> 0.15 | N33: =MAX(0,MIN(0.95,$N32-$AA32+IF(AND($D32="raise_resistance",$E32="financing",$G32="NO"),$F32,0))) -> 0.2 | O33: =IF(AND($D32="lock_lane",$G32="NO"),$E32,"") | P33: =1+$AB32 -> 1 | Q33: =SUMIFS($Q$37:$Q$76,$A$37:$A$76,$A33) -> 0 | R33: =IF(AND($D33="shave_value",$G33="NO"),$S32*$F33,0) -> 0 | S33: =MIN($B$4,MAX(0,$S32+$Q33-$R33)) -> 30000 | T33: =IFERROR($S33/$B$4,0) -> 1 | U33: =SUMIFS($G$37:$G$76,$A$37:$A$76,$A33) -> 0 | V33: =SUMIFS($H$37:$H$76,$A$37:$A$76,$A33) -> 0 | W33: =MAX(0,$C33-$V33) -> 0 | X33: =MAX(0,MIN($B$8,$X32-$U33-$W33-IF($A33<=MAX($A$37:$A$76),Assumptions!$B$7,0))) -> 0 | Y33: =SUMIFS($J$37:$J$76,$A$37:$A$76,$A33,$E$37:$E$76,"vehicle") -> 0 | Z33: =SUMIFS($J$37:$J$76,$A$37:$A$76,$A33,$E$37:$E$76,"protection") -> 0 | AA33: =SUMIFS($J$37:$J$76,$A$37:$A$76,$A33,$E$37:$E$76,"financing") -> 0 | AB33: =SUMIFS($K$37:$K$76,$A$37:$A$76,$A33) -> 0 | AC33: =IF(AND($D33="drain_energy",$G33="NO"),$F33,0) -> 0 | AD33: =IF(OR($A33>MAX($A$37:$A$76),$X32<=0),"-",IF($S33>=$B$7,"MAX CLOSE",IF($S33>=$B$6,"STRONG CLOSE",IF($S33>=$B$5,"SALE AVAILABLE","BUILDING")))&IF($X33<=0," / THEY WALKED","")) -> - | AE33: =IF($X32>0,$S33,0) -> 0
A35: Probes and buffs apply at the END of a turn - they change the NEXT turn. Shield applies to THIS turn's objection and expires unused.
A36: Turn | B36: Card ID | C36: Target Lane | D36: Name | E36: Lane Used | F36: Energy | G36: Patience Cost | H36: Shield | I36: Counters | J36: Res. Reduction | K36: Buff | L36: Value (% budget) | M36: Face Value ($) | N36: Resistance @ Play | O36: Value Mult | P36: Lane Locked? | Q36: Effective Value
A37: 1 | B37: probe_needs | C37: financing | D37: =IFERROR(INDEX(Cards!$B$4:$B$25,MATCH($B37,Cards!$A$4:$A$25,0)),"") -> Probe Needs | E37: =IFERROR(IF(INDEX(Cards!$C$4:$C$25,MATCH($B37,Cards!$A$4:$A$25,0))="any",$C37,INDEX(Cards!$C$4:$C$25,MATCH($B37,Cards!$A$4:$A$25,0))),"") -> financing | F37: =IFERROR(INDEX(Cards!$D$4:$D$25,MATCH($B37,Cards!$A$4:$A$25,0)),0) -> 1 | G37: =IFERROR(INDEX(Cards!$E$4:$E$25,MATCH($B37,Cards!$A$4:$A$25,0)),0) -> 0 | H37: =IFERROR(INDEX(Cards!$I$4:$I$25,MATCH($B37,Cards!$A$4:$A$25,0)),0) -> 0 | I37: =IFERROR(IF(INDEX(Cards!$J$4:$J$25,MATCH($B37,Cards!$A$4:$A$25,0))=0,"",INDEX(Cards!$J$4:$J$25,MATCH($B37,Cards!$A$4:$A$25,0))),"") | J37: =IFERROR(INDEX(Cards!$H$4:$H$25,MATCH($B37,Cards!$A$4:$A$25,0)),0) -> 0.2 | K37: =IFERROR(INDEX(Cards!$L$4:$L$25,MATCH($B37,Cards!$A$4:$A$25,0)),0) -> 0 | L37: =IFERROR(INDEX(Cards!$G$4:$G$25,MATCH($B37,Cards!$A$4:$A$25,0)),0) -> 0 | M37: =$L37*$B$4*Assumptions!$B$15 -> 0 | N37: =IFERROR(IF($E37="vehicle",INDEX($L$22:$L$33,MATCH($A37,$A$22:$A$33,0)),IF($E37="protection",INDEX($M$22:$M$33,MATCH($A37,$A$22:$A$33,0)),IF($E37="financing",INDEX($N$22:$N$33,MATCH($A37,$A$22:$A$33,0)),0))),0) -> 0.4 | O37: =IFERROR(INDEX($P$22:$P$33,MATCH($A37,$A$22:$A$33,0)),1) -> 1 | P37: =IFERROR(IF(AND($E37<>"",$E37=INDEX($O$22:$O$33,MATCH($A37,$A$22:$A$33,0))),"LOCKED",""),"") | Q37: =IF($P37="LOCKED",0,$M37*(1-$N37)*$O37) -> 0
A38: 1 | B38: small_talk | D38: =IFERROR(INDEX(Cards!$B$4:$B$25,MATCH($B38,Cards!$A$4:$A$25,0)),"") -> Small Talk | E38: =IFERROR(IF(INDEX(Cards!$C$4:$C$25,MATCH($B38,Cards!$A$4:$A$25,0))="any",$C38,INDEX(Cards!$C$4:$C$25,MATCH($B38,Cards!$A$4:$A$25,0))),"") -> none | F38: =IFERROR(INDEX(Cards!$D$4:$D$25,MATCH($B38,Cards!$A$4:$A$25,0)),0) -> 0 | G38: =IFERROR(INDEX(Cards!$E$4:$E$25,MATCH($B38,Cards!$A$4:$A$25,0)),0) -> 0 | H38: =IFERROR(INDEX(Cards!$I$4:$I$25,MATCH($B38,Cards!$A$4:$A$25,0)),0) -> 4 | I38: =IFERROR(IF(INDEX(Cards!$J$4:$J$25,MATCH($B38,Cards!$A$4:$A$25,0))=0,"",INDEX(Cards!$J$4:$J$25,MATCH($B38,Cards!$A$4:$A$25,0))),"") | J38: =IFERROR(INDEX(Cards!$H$4:$H$25,MATCH($B38,Cards!$A$4:$A$25,0)),0) -> 0 | K38: =IFERROR(INDEX(Cards!$L$4:$L$25,MATCH($B38,Cards!$A$4:$A$25,0)),0) -> 0 | L38: =IFERROR(INDEX(Cards!$G$4:$G$25,MATCH($B38,Cards!$A$4:$A$25,0)),0) -> 0 | M38: =$L38*$B$4*Assumptions!$B$15 -> 0 | N38: =IFERROR(IF($E38="vehicle",INDEX($L$22:$L$33,MATCH($A38,$A$22:$A$33,0)),IF($E38="protection",INDEX($M$22:$M$33,MATCH($A38,$A$22:$A$33,0)),IF($E38="financing",INDEX($N$22:$N$33,MATCH($A38,$A$22:$A$33,0)),0))),0) -> 0 | O38: =IFERROR(INDEX($P$22:$P$33,MATCH($A38,$A$22:$A$33,0)),1) -> 1 | P38: =IFERROR(IF(AND($E38<>"",$E38=INDEX($O$22:$O$33,MATCH($A38,$A$22:$A$33,0))),"LOCKED",""),"") | Q38: =IF($P38="LOCKED",0,$M38*(1-$N38)*$O38) -> 0
A39: 1 | B39: base_trim_pitch | D39: =IFERROR(INDEX(Cards!$B$4:$B$25,MATCH($B39,Cards!$A$4:$A$25,0)),"") -> Base Trim Pitch | E39: =IFERROR(IF(INDEX(Cards!$C$4:$C$25,MATCH($B39,Cards!$A$4:$A$25,0))="any",$C39,INDEX(Cards!$C$4:$C$25,MATCH($B39,Cards!$A$4:$A$25,0))),"") -> vehicle | F39: =IFERROR(INDEX(Cards!$D$4:$D$25,MATCH($B39,Cards!$A$4:$A$25,0)),0) -> 1 | G39: =IFERROR(INDEX(Cards!$E$4:$E$25,MATCH($B39,Cards!$A$4:$A$25,0)),0) -> 0 | H39: =IFERROR(INDEX(Cards!$I$4:$I$25,MATCH($B39,Cards!$A$4:$A$25,0)),0) -> 0 | I39: =IFERROR(IF(INDEX(Cards!$J$4:$J$25,MATCH($B39,Cards!$A$4:$A$25,0))=0,"",INDEX(Cards!$J$4:$J$25,MATCH($B39,Cards!$A$4:$A$25,0))),"") | J39: =IFERROR(INDEX(Cards!$H$4:$H$25,MATCH($B39,Cards!$A$4:$A$25,0)),0) -> 0 | K39: =IFERROR(INDEX(Cards!$L$4:$L$25,MATCH($B39,Cards!$A$4:$A$25,0)),0) -> 0 | L39: =IFERROR(INDEX(Cards!$G$4:$G$25,MATCH($B39,Cards!$A$4:$A$25,0)),0) -> 0.0833 | M39: =$L39*$B$4*Assumptions!$B$15 -> 4123.35 | N39: =IFERROR(IF($E39="vehicle",INDEX($L$22:$L$33,MATCH($A39,$A$22:$A$33,0)),IF($E39="protection",INDEX($M$22:$M$33,MATCH($A39,$A$22:$A$33,0)),IF($E39="financing",INDEX($N$22:$N$33,MATCH($A39,$A$22:$A$33,0)),0))),0) -> 0.3 | O39: =IFERROR(INDEX($P$22:$P$33,MATCH($A39,$A$22:$A$33,0)),1) -> 1 | P39: =IFERROR(IF(AND($E39<>"",$E39=INDEX($O$22:$O$33,MATCH($A39,$A$22:$A$33,0))),"LOCKED",""),"") | Q39: =IF($P39="LOCKED",0,$M39*(1-$N39)*$O39) -> 2886.345
A40: 2 | B40: justify_the_value | D40: =IFERROR(INDEX(Cards!$B$4:$B$25,MATCH($B40,Cards!$A$4:$A$25,0)),"") -> Justify The Value | E40: =IFERROR(IF(INDEX(Cards!$C$4:$C$25,MATCH($B40,Cards!$A$4:$A$25,0))="any",$C40,INDEX(Cards!$C$4:$C$25,MATCH($B40,Cards!$A$4:$A$25,0))),"") -> none | F40: =IFERROR(INDEX(Cards!$D$4:$D$25,MATCH($B40,Cards!$A$4:$A$25,0)),0) -> 1 | G40: =IFERROR(INDEX(Cards!$E$4:$E$25,MATCH($B40,Cards!$A$4:$A$25,0)),0) -> 0 | H40: =IFERROR(INDEX(Cards!$I$4:$I$25,MATCH($B40,Cards!$A$4:$A$25,0)),0) -> 4 | I40: =IFERROR(IF(INDEX(Cards!$J$4:$J$25,MATCH($B40,Cards!$A$4:$A$25,0))=0,"",INDEX(Cards!$J$4:$J$25,MATCH($B40,Cards!$A$4:$A$25,0))),"") -> dont_need_extras | J40: =IFERROR(INDEX(Cards!$H$4:$H$25,MATCH($B40,Cards!$A$4:$A$25,0)),0) -> 0 | K40: =IFERROR(INDEX(Cards!$L$4:$L$25,MATCH($B40,Cards!$A$4:$A$25,0)),0) -> 0 | L40: =IFERROR(INDEX(Cards!$G$4:$G$25,MATCH($B40,Cards!$A$4:$A$25,0)),0) -> 0 | M40: =$L40*$B$4*Assumptions!$B$15 -> 0 | N40: =IFERROR(IF($E40="vehicle",INDEX($L$22:$L$33,MATCH($A40,$A$22:$A$33,0)),IF($E40="protection",INDEX($M$22:$M$33,MATCH($A40,$A$22:$A$33,0)),IF($E40="financing",INDEX($N$22:$N$33,MATCH($A40,$A$22:$A$33,0)),0))),0) -> 0 | O40: =IFERROR(INDEX($P$22:$P$33,MATCH($A40,$A$22:$A$33,0)),1) -> 1 | P40: =IFERROR(IF(AND($E40<>"",$E40=INDEX($O$22:$O$33,MATCH($A40,$A$22:$A$33,0))),"LOCKED",""),"") | Q40: =IF($P40="LOCKED",0,$M40*(1-$N40)*$O40) -> 0
A41: 2 | B41: upsell_package | D41: =IFERROR(INDEX(Cards!$B$4:$B$25,MATCH($B41,Cards!$A$4:$A$25,0)),"") -> Upsell Package | E41: =IFERROR(IF(INDEX(Cards!$C$4:$C$25,MATCH($B41,Cards!$A$4:$A$25,0))="any",$C41,INDEX(Cards!$C$4:$C$25,MATCH($B41,Cards!$A$4:$A$25,0))),"") -> vehicle | F41: =IFERROR(INDEX(Cards!$D$4:$D$25,MATCH($B41,Cards!$A$4:$A$25,0)),0) -> 2 | G41: =IFERROR(INDEX(Cards!$E$4:$E$25,MATCH($B41,Cards!$A$4:$A$25,0)),0) -> 3 | H41: =IFERROR(INDEX(Cards!$I$4:$I$25,MATCH($B41,Cards!$A$4:$A$25,0)),0) -> 0 | I41: =IFERROR(IF(INDEX(Cards!$J$4:$J$25,MATCH($B41,Cards!$A$4:$A$25,0))=0,"",INDEX(Cards!$J$4:$J$25,MATCH($B41,Cards!$A$4:$A$25,0))),"") | J41: =IFERROR(INDEX(Cards!$H$4:$H$25,MATCH($B41,Cards!$A$4:$A$25,0)),0) -> 0 | K41: =IFERROR(INDEX(Cards!$L$4:$L$25,MATCH($B41,Cards!$A$4:$A$25,0)),0) -> 0 | L41: =IFERROR(INDEX(Cards!$G$4:$G$25,MATCH($B41,Cards!$A$4:$A$25,0)),0) -> 0.1667 | M41: =$L41*$B$4*Assumptions!$B$15 -> 8251.65 | N41: =IFERROR(IF($E41="vehicle",INDEX($L$22:$L$33,MATCH($A41,$A$22:$A$33,0)),IF($E41="protection",INDEX($M$22:$M$33,MATCH($A41,$A$22:$A$33,0)),IF($E41="financing",INDEX($N$22:$N$33,MATCH($A41,$A$22:$A$33,0)),0))),0) -> 0.3 | O41: =IFERROR(INDEX($P$22:$P$33,MATCH($A41,$A$22:$A$33,0)),1) -> 1 | P41: =IFERROR(IF(AND($E41<>"",$E41=INDEX($O$22:$O$33,MATCH($A41,$A$22:$A$33,0))),"LOCKED",""),"") | Q41: =IF($P41="LOCKED",0,$M41*(1-$N41)*$O41) -> 5776.155
A42: 3 | B42: build_rapport | D42: =IFERROR(INDEX(Cards!$B$4:$B$25,MATCH($B42,Cards!$A$4:$A$25,0)),"") -> Build Rapport | E42: =IFERROR(IF(INDEX(Cards!$C$4:$C$25,MATCH($B42,Cards!$A$4:$A$25,0))="any",$C42,INDEX(Cards!$C$4:$C$25,MATCH($B42,Cards!$A$4:$A$25,0))),"") -> none | F42: =IFERROR(INDEX(Cards!$D$4:$D$25,MATCH($B42,Cards!$A$4:$A$25,0)),0) -> 1 | G42: =IFERROR(INDEX(Cards!$E$4:$E$25,MATCH($B42,Cards!$A$4:$A$25,0)),0) -> 0 | H42: =IFERROR(INDEX(Cards!$I$4:$I$25,MATCH($B42,Cards!$A$4:$A$25,0)),0) -> 10 | I42: =IFERROR(IF(INDEX(Cards!$J$4:$J$25,MATCH($B42,Cards!$A$4:$A$25,0))=0,"",INDEX(Cards!$J$4:$J$25,MATCH($B42,Cards!$A$4:$A$25,0))),"") | J42: =IFERROR(INDEX(Cards!$H$4:$H$25,MATCH($B42,Cards!$A$4:$A$25,0)),0) -> 0 | K42: =IFERROR(INDEX(Cards!$L$4:$L$25,MATCH($B42,Cards!$A$4:$A$25,0)),0) -> 0 | L42: =IFERROR(INDEX(Cards!$G$4:$G$25,MATCH($B42,Cards!$A$4:$A$25,0)),0) -> 0 | M42: =$L42*$B$4*Assumptions!$B$15 -> 0 | N42: =IFERROR(IF($E42="vehicle",INDEX($L$22:$L$33,MATCH($A42,$A$22:$A$33,0)),IF($E42="protection",INDEX($M$22:$M$33,MATCH($A42,$A$22:$A$33,0)),IF($E42="financing",INDEX($N$22:$N$33,MATCH($A42,$A$22:$A$33,0)),0))),0) -> 0 | O42: =IFERROR(INDEX($P$22:$P$33,MATCH($A42,$A$22:$A$33,0)),1) -> 1 | P42: =IFERROR(IF(AND($E42<>"",$E42=INDEX($O$22:$O$33,MATCH($A42,$A$22:$A$33,0))),"LOCKED",""),"") | Q42: =IF($P42="LOCKED",0,$M42*(1-$N42)*$O42) -> 0
A43: 3 | B43: extended_warranty | D43: =IFERROR(INDEX(Cards!$B$4:$B$25,MATCH($B43,Cards!$A$4:$A$25,0)),"") -> Extended Warranty | E43: =IFERROR(IF(INDEX(Cards!$C$4:$C$25,MATCH($B43,Cards!$A$4:$A$25,0))="any",$C43,INDEX(Cards!$C$4:$C$25,MATCH($B43,Cards!$A$4:$A$25,0))),"") -> protection | F43: =IFERROR(INDEX(Cards!$D$4:$D$25,MATCH($B43,Cards!$A$4:$A$25,0)),0) -> 2 | G43: =IFERROR(INDEX(Cards!$E$4:$E$25,MATCH($B43,Cards!$A$4:$A$25,0)),0) -> 4 | H43: =IFERROR(INDEX(Cards!$I$4:$I$25,MATCH($B43,Cards!$A$4:$A$25,0)),0) -> 0 | I43: =IFERROR(IF(INDEX(Cards!$J$4:$J$25,MATCH($B43,Cards!$A$4:$A$25,0))=0,"",INDEX(Cards!$J$4:$J$25,MATCH($B43,Cards!$A$4:$A$25,0))),"") | J43: =IFERROR(INDEX(Cards!$H$4:$H$25,MATCH($B43,Cards!$A$4:$A$25,0)),0) -> 0 | K43: =IFERROR(INDEX(Cards!$L$4:$L$25,MATCH($B43,Cards!$A$4:$A$25,0)),0) -> 0 | L43: =IFERROR(INDEX(Cards!$G$4:$G$25,MATCH($B43,Cards!$A$4:$A$25,0)),0) -> 0.1333 | M43: =$L43*$B$4*Assumptions!$B$15 -> 6598.35 | N43: =IFERROR(IF($E43="vehicle",INDEX($L$22:$L$33,MATCH($A43,$A$22:$A$33,0)),IF($E43="protection",INDEX($M$22:$M$33,MATCH($A43,$A$22:$A$33,0)),IF($E43="financing",INDEX($N$22:$N$33,MATCH($A43,$A$22:$A$33,0)),0))),0) -> 0.15 | O43: =IFERROR(INDEX($P$22:$P$33,MATCH($A43,$A$22:$A$33,0)),1) -> 1 | P43: =IFERROR(IF(AND($E43<>"",$E43=INDEX($O$22:$O$33,MATCH($A43,$A$22:$A$33,0))),"LOCKED",""),"") | Q43: =IF($P43="LOCKED",0,$M43*(1-$N43)*$O43) -> 5608.5975
...

Sheet Balance Check
A1: BALANCE CHECK - can you close at all while paying the objection tax?
A2: All formulas. Change Assumptions, Cards, Objections or Customers and this updates.
A4: Archetype | B4: Budget | C4: Patience | D4: Avg Obj. Damage | E4: Turns Before Walk | F4: Total Energy | G4: Energy on Shield | H4: Energy for Value | I4: Req. Value/Energy (Sale) | J4: Req. Value/Energy (Max) | K4: Pool Avg Value/Energy | L4: Avg Resistance | M4: Pool Effective Value/Energy | N4: Verdict
A5: =Customers!$B$4 -> Budget Buyer | B5: =Customers!$C$4 -> 18000 | C5: =Customers!$D$4 -> 48 | D5: =(IFERROR(INDEX(Objections!$C$4:$C$8,MATCH(Customers!$K$4,Objections!$A$4:$A$8,0)),0)+IFERROR(INDEX(Objections!$C$4:$C$8,MATCH(Customers!$L$4,Objections!$A$4:$A$8,0)),0)+IFERROR(INDEX(Objections!$C$4:$C$8,MATCH(Customers!$M$4,Objections!$A$4:$A$8,0)),0))/3 -> 6.6666667 | E5: =IFERROR($C5/($D5+Assumptions!$B$7),0) -> 5.5384615 | F5: =$E5*Assumptions!$B$4 -> 16.615385 | G5: =IFERROR($E5*($D5/AVERAGEIFS(Cards!$I$4:$I$25,Cards!$I$4:$I$25,">0")),0) -> 7.3846154 | H5: =MAX(0,$F5-$G5) -> 9.2307692 | I5: =IFERROR(Customers!$H$4/$H5,0) -> 1170 | J5: =IFERROR(Customers!$J$4/$H5,0) -> 1950 | K5: =IFERROR(AVERAGEIFS(Cards!$P$4:$P$25,Cards!$G$4:$G$25,">0")/AVERAGEIFS(Cards!$D$4:$D$25,Cards!$G$4:$G$25,">0")*($B5/30000),0) -> 2326.5 | L5: =AVERAGE(Customers!$E$4:$G$4) -> 0.38333333 | M5: =$K5*(1-$L5) -> 1434.675 | N5: =IF($M5>=$J5,"MAX CLOSE FEASIBLE",IF($M5>=$I5,"SALE ONLY","TOO HARD")) -> SALE ONLY
A6: =Customers!$B$5 -> Family First | B6: =Customers!$C$5 -> 30000 | C6: =Customers!$D$5 -> 50 | D6: =(IFERROR(INDEX(Objections!$C$4:$C$8,MATCH(Customers!$K$5,Objections!$A$4:$A$8,0)),0)+IFERROR(INDEX(Objections!$C$4:$C$8,MATCH(Customers!$L$5,Objections!$A$4:$A$8,0)),0)+IFERROR(INDEX(Objections!$C$4:$C$8,MATCH(Customers!$M$5,Objections!$A$4:$A$8,0)),0))/3 -> 6.6666667 | E6: =IFERROR($C6/($D6+Assumptions!$B$7),0) -> 5.7692308 | F6: =$E6*Assumptions!$B$4 -> 17.307692 | G6: =IFERROR($E6*($D6/AVERAGEIFS(Cards!$I$4:$I$25,Cards!$I$4:$I$25,">0")),0) -> 7.6923077 | H6: =MAX(0,$F6-$G6) -> 9.6153846 | I6: =IFERROR(Customers!$H$5/$H6,0) -> 1872 | J6: =IFERROR(Customers!$J$5/$H6,0) -> 3120 | K6: =IFERROR(AVERAGEIFS(Cards!$P$4:$P$25,Cards!$G$4:$G$25,">0")/AVERAGEIFS(Cards!$D$4:$D$25,Cards!$G$4:$G$25,">0")*($B6/30000),0) -> 3877.5 | L6: =AVERAGE(Customers!$E$5:$G$5) -> 0.28333333 | M6: =$K6*(1-$L6) -> 2778.875 | N6: =IF($M6>=$J6,"MAX CLOSE FEASIBLE",IF($M6>=$I6,"SALE ONLY","TOO HARD")) -> SALE ONLY
A7: =Customers!$B$6 -> Tech Enthusiast | B7: =Customers!$C$6 -> 40000 | C7: =Customers!$D$6 -> 44 | D7: =(IFERROR(INDEX(Objections!$C$4:$C$8,MATCH(Customers!$K$6,Objections!$A$4:$A$8,0)),0)+IFERROR(INDEX(Objections!$C$4:$C$8,MATCH(Customers!$L$6,Objections!$A$4:$A$8,0)),0)+IFERROR(INDEX(Objections!$C$4:$C$8,MATCH(Customers!$M$6,Objections!$A$4:$A$8,0)),0))/3 -> 6 | E7: =IFERROR($C7/($D7+Assumptions!$B$7),0) -> 5.5 | F7: =$E7*Assumptions!$B$4 -> 16.5 | G7: =IFERROR($E7*($D7/AVERAGEIFS(Cards!$I$4:$I$25,Cards!$I$4:$I$25,">0")),0) -> 6.6 | H7: =MAX(0,$F7-$G7) -> 9.9 | I7: =IFERROR(Customers!$H$6/$H7,0) -> 2424.2424 | J7: =IFERROR(Customers!$J$6/$H7,0) -> 4040.404 | K7: =IFERROR(AVERAGEIFS(Cards!$P$4:$P$25,Cards!$G$4:$G$25,">0")/AVERAGEIFS(Cards!$D$4:$D$25,Cards!$G$4:$G$25,">0")*($B7/30000),0) -> 5170 | L7: =AVERAGE(Customers!$E$6:$G$6) -> 0.26666667 | M7: =$K7*(1-$L7) -> 3791.3333 | N7: =IF($M7>=$J7,"MAX CLOSE FEASIBLE",IF($M7>=$I7,"SALE ONLY","TOO HARD")) -> SALE ONLY
A10: HOW TO READ THIS
A11: - Turns Before Walk now accounts for objection damage as well as passive decay - it is much shorter than it was before the customer started fighting back.
A12: - Energy on Shield is the rough cost of surviving: damage per turn divided by shield per rapport card.
A13: - Energy for Value is what is actually LEFT to build the deal. That is the number the objection system is designed to squeeze.
A14: - This ignores probing, counters and escalation, so it is a rough OPTIMISTIC ceiling. If it says TOO HARD, the real game is worse. Cross-check against sim.py, which models all of it.
A16: CARD POOL SUMMARY
A17: Cards in pool | B17: =COUNTA(Cards!$A$4:$A$25) -> 22
A18: Flagged Starter | B18: =COUNTIF(Cards!$O$4:$O$25,"YES") -> 10
A19: Value cards | B19: =COUNTIF(Cards!$G$4:$G$25,">0") -> 9
A20: Shield cards | B20: =COUNTIF(Cards!$I$4:$I$25,">0") -> 8
A21: Counter cards | B21: =COUNTIF(Cards!$J$4:$J$25,"<>") -> 4
A22: Total shield available | B22: =SUM(Cards!$I$4:$I$25) -> 40
A23: Objections defined | B23: =COUNTA(Objections!$A$4:$A$8) -> 5
A24: Objections with riders | B24: =COUNTIF(Objections!$D$4:$D$8,"<>-") -> 4

Sheet Print & Play
A1: PRINT & PLAY - cut into strips and negotiate on paper
A2: Live formulas from the Cards and Objections tabs, so this never drifts out of sync.
A4: Card | B4: Cost | C4: Effect | D4: Flavour
A5: =Cards!$B$4 -> Base Trim Pitch | B5: =Cards!$D$4&" energy" -> 1 energy | C5: =IF(Cards!$G$4>0,"+"&TEXT(Cards!$G$4,"0.0%")&" of budget in "&Cards!$C$4&". ","")&IF(Cards!$I$4>0,"Shield "&Cards!$I$4&". ","")&IF(Cards!$J$4<>"","Counters: "&Cards!$J$4&". ","")&IF(Cards!$H$4>0,"-"&TEXT(Cards!$H$4,"0%")&" resistance. ","")&IF(Cards!$K$4>0,"Draw "&Cards!$K$4&". ","")&IF(Cards!$L$4>0,"Next turn +"&TEXT(Cards!$L$4,"0%")&" value. ","")&IF(Cards!$E$4>0,"Costs "&Cards!$E$4&" patience.","") -> +8.3% of budget in vehicle. | D5: =Cards!$Q$4 -> It's the same car, just with fewer things that work.
A6: =Cards!$B$5 -> Upsell Package | B6: =Cards!$D$5&" energy" -> 2 energy | C6: =IF(Cards!$G$5>0,"+"&TEXT(Cards!$G$5,"0.0%")&" of budget in "&Cards!$C$5&". ","")&IF(Cards!$I$5>0,"Shield "&Cards!$I$5&". ","")&IF(Cards!$J$5<>"","Counters: "&Cards!$J$5&". ","")&IF(Cards!$H$5>0,"-"&TEXT(Cards!$H$5,"0%")&" resistance. ","")&IF(Cards!$K$5>0,"Draw "&Cards!$K$5&". ","")&IF(Cards!$L$5>0,"Next turn +"&TEXT(Cards!$L$5,"0%")&" value. ","")&IF(Cards!$E$5>0,"Costs "&Cards!$E$5&" patience.","") -> +16.7% of budget in vehicle. Costs 3 patience. | D6: =Cards!$Q$5 -> The Platinum Ultra trim adds heated cupholders and five grand.
A7: =Cards!$B$6 -> Highlight Features | B7: =Cards!$D$6&" energy" -> 1 energy | C7: =IF(Cards!$G$6>0,"+"&TEXT(Cards!$G$6,"0.0%")&" of budget in "&Cards!$C$6&". ","")&IF(Cards!$I$6>0,"Shield "&Cards!$I$6&". ","")&IF(Cards!$J$6<>"","Counters: "&Cards!$J$6&". ","")&IF(Cards!$H$6>0,"-"&TEXT(Cards!$H$6,"0%")&" resistance. ","")&IF(Cards!$K$6>0,"Draw "&Cards!$K$6&". ","")&IF(Cards!$L$6>0,"Next turn +"&TEXT(Cards!$L$6,"0%")&" value. ","")&IF(Cards!$E$6>0,"Costs "&Cards!$E$6&" patience.","") -> -15% resistance. | D7: =Cards!$Q$6 -> Watch me open the trunk with my foot. Now you need it.
A8: =Cards!$B$7 -> Extended Warranty | B8: =Cards!$D$7&" energy" -> 2 energy | C8: =IF(Cards!$G$7>0,"+"&TEXT(Cards!$G$7,"0.0%")&" of budget in "&Cards!$C$7&". ","")&IF(Cards!$I$7>0,"Shield "&Cards!$I$7&". ","")&IF(Cards!$J$7<>"","Counters: "&Cards!$J$7&". ","")&IF(Cards!$H$7>0,"-"&TEXT(Cards!$H$7,"0%")&" resistance. ","")&IF(Cards!$K$7>0,"Draw "&Cards!$K$7&". ","")&IF(Cards!$L$7>0,"Next turn +"&TEXT(Cards!$L$7,"0%")&" value. ","")&IF(Cards!$E$7>0,"Costs "&Cards!$E$7&" patience.","") -> +13.3% of budget in protection. Costs 4 patience. | D8: =Cards!$Q$7 -> Statistically you will never use this. Emotionally, you need it.
A9: =Cards!$B$8 -> Gap Insurance | B9: =Cards!$D$8&" energy" -> 1 energy | C9: =IF(Cards!$G$8>0,"+"&TEXT(Cards!$G$8,"0.0%")&" of budget in "&Cards!$C$8&". ","")&IF(Cards!$I$8>0,"Shield "&Cards!$I$8&". ","")&IF(Cards!$J$8<>"","Counters: "&Cards!$J$8&". ","")&IF(Cards!$H$8>0,"-"&TEXT(Cards!$H$8,"0%")&" resistance. ","")&IF(Cards!$K$8>0,"Draw "&Cards!$K$8&". ","")&IF(Cards!$L$8>0,"Next turn +"&TEXT(Cards!$L$8,"0%")&" value. ","")&IF(Cards!$E$8>0,"Costs "&Cards!$E$8&" patience.","") -> +7.3% of budget in protection. Costs 2 patience. | D9: =Cards!$Q$8 -> In case the car dies before the loan does.
A10: =Cards!$B$9 -> Paint Protection | B10: =Cards!$D$9&" energy" -> 1 energy | C10: =IF(Cards!$G$9>0,"+"&TEXT(Cards!$G$9,"0.0%")&" of budget in "&Cards!$C$9&". ","")&IF(Cards!$I$9>0,"Shield "&Cards!$I$9&". ","")&IF(Cards!$J$9<>"","Counters: "&Cards!$J$9&". ","")&IF(Cards!$H$9>0,"-"&TEXT(Cards!$H$9,"0%")&" resistance. ","")&IF(Cards!$K$9>0,"Draw "&Cards!$K$9&". ","")&IF(Cards!$L$9>0,"Next turn +"&TEXT(Cards!$L$9,"0%")&" value. ","")&IF(Cards!$E$9>0,"Costs "&Cards!$E$9&" patience.","") -> +6.0% of budget in protection. Costs 3 patience. | D10: =Cards!$Q$9 -> It's wax. It is forty dollars of wax.
A11: =Cards!$B$10 -> Rate Markup | B11: =Cards!$D$10&" energy" -> 1 energy | C11: =IF(Cards!$G$10>0,"+"&TEXT(Cards!$G$10,"0.0%")&" of budget in "&Cards!$C$10&". ","")&IF(Cards!$I$10>0,"Shield "&Cards!$I$10&". ","")&IF(Cards!$J$10<>"","Counters: "&Cards!$J$10&". ","")&IF(Cards!$H$10>0,"-"&TEXT(Cards!$H$10,"0%")&" resistance. ","")&IF(Cards!$K$10>0,"Draw "&Cards!$K$10&". ","")&IF(Cards!$L$10>0,"Next turn +"&TEXT(Cards!$L$10,"0%")&" value. ","")&IF(Cards!$E$10>0,"Costs "&Cards!$E$10&" patience.","") -> +6.7% of budget in financing. Costs 5 patience. | D11: =Cards!$Q$10 -> The bank said 4.9. I'm going to say 7.9 and see what happens.
